<robot name="little_dog">

  <link name="floor">
    <visual>
      <origin xyz="0 0 -0.05"/>
      <geometry>
        <box size="2.5 2.5 0.1"/>
      </geometry>
    </visual>
  </link>







  <link name="body">
    <inertial>
      <mass value="1.800000" />
      <inertia ixx="0.001625" ixy="0" ixz="0" iyy="0.009178" iyz="0" izz="0.008794" />
    </inertial>
    <visual>
      <geometry>
        <mesh filename="/home/blandry/.julia/dev/Bilevel/urdf/little_dog/meshes/body.obj"/>
      </geometry>
      <material name="black">
      	<color rgba="0.1 0.1 0.1 1" />
      </material>
    </visual>
  </link>

  <joint name="floor_to_body" type="floating">
    <parent link="floor"/>
    <child link="body"/>
    <origin xyz="0 0 0"/>
  </joint>






  <link name="front_left_hip">
    <inertial>
      <origin xyz="0.000000 0.002900 0.000000" rpy="0 0 0" />
      <mass value="0.062300" />
      <inertia ixx="0.000004" ixy="0" ixz="0" iyy="0.000015" iyz="0" izz="0.000015" />
    </inertial>
  </link>

  <joint name="front_left_hip_roll" type="revolute">
    <parent link="body" />
    <child link="front_left_hip" />
    <origin xyz="0.101000 0.036250 0.000000" />
    <axis xyz="1 0 0" />
    <limit lower="-.6" upper=".6"/>
  </joint>

  <link name="front_left_upper_leg">
    <inertial>
      <origin xyz="0.000000 0.000000 -0.016600" rpy="0 0 0" />
      <mass value="0.127900" />
      <inertia ixx="0.000082" ixy="0" ixz="0" iyy="0.000089" iyz="0" izz="0.000015" />
    </inertial>
    <visual>
      <origin xyz="0 0 0" rpy="0 0 0" />
      <geometry>
        <mesh filename="/home/blandry/.julia/dev/Bilevel/urdf/little_dog/meshes/front_left_upper.obj"/>
      </geometry>
      <material name="black" />
    </visual>
  </link>

  <joint name="front_left_hip_pitch" type="revolute">
    <parent link="front_left_hip" />
    <child link="front_left_upper_leg" />
    <origin xyz="0 0.0236 0" />
    <axis xyz="0 1 0" />
    <limit lower="-3.5" upper="2.4"/>
  </joint>

  <link name="front_left_lower_leg">
  <inertial>
    <origin xyz="0.000000 0.000000 -0.020200" rpy="0 0 0" />
    <mass value="0.046400" />
    <inertia ixx="0.000038" ixy="0" ixz="0" iyy="0.000035" iyz="0" izz="0.000004" />
  </inertial>
  <visual>
    <origin xyz="0 0 0" rpy="0 0 0" />
    <geometry>
      <mesh filename="/home/blandry/.julia/dev/Bilevel/urdf/little_dog/meshes/front_left_lower.obj"/>
    </geometry>
    <material name="black" />
  </visual>
  <!-- <collision group="left_lower_legs">
    <origin xyz="-0.0265 0 -0.048" />
    <geometry>
      <capsule radius="0.012" length="0.09" />
    </geometry>
  </collision> -->
  <collision group="feet">
    <origin xyz="-0.0265 0 -0.0985"/>
    <geometry>
      <sphere radius="0"/>
    </geometry>
  </collision>
</link>

<joint name="front_left_knee" type="revolute">
  <parent link="front_left_upper_leg" />
  <child link="front_left_lower_leg" />
  <origin xyz="0 0 -0.0751" />
  <axis xyz="0 1 0" />
  <limit lower="-3.1" upper="1.0"/>
</joint>





<link name="front_right_hip">
  <inertial>
    <origin xyz="0.000000 -0.002900 0.000000" rpy="0 0 0" />
    <mass value="0.062300" />
    <inertia ixx="0.000004" ixy="0" ixz="0" iyy="0.000015" iyz="0" izz="0.000015" />
  </inertial>
 </link>

 <joint name="front_right_hip_roll" type="revolute">
   <parent link="body" />
   <child link="front_right_hip" />
   <origin xyz="0.101000 -0.036250 0.000000" />
   <axis xyz="1 0 0" />
   <limit lower="-.6" upper=".6"/>
 </joint>

 <link name="front_right_upper_leg">
  <inertial>
    <origin xyz="0.000000 0.000000 -0.016600" rpy="0 0 0" />
    <mass value="0.127900" />
    <inertia ixx="0.000082" ixy="0" ixz="0" iyy="0.000089" iyz="0" izz="0.000015" />
  </inertial>
  <visual>
    <origin xyz="0 0 0" rpy="0 0 0" />
    <geometry>
      <mesh filename="/home/blandry/.julia/dev/Bilevel/urdf/little_dog/meshes/front_right_upper.obj"/>
    </geometry>
    <material name="black"/>
  </visual>
  </link>

  <joint name="front_right_hip_pitch" type="revolute">
    <parent link="front_right_hip" />
    <child link="front_right_upper_leg" />
    <origin xyz="0 -0.0236 0" />
    <axis xyz="0 1 0" />
    <limit lower="-3.5" upper="2.4"/>
  </joint>

  <link name="front_right_lower_leg">
  <inertial>
    <origin xyz="0.000000 0.000000 -0.020200" rpy="0 0 0" />
    <mass value="0.046400" />
    <inertia ixx="0.000038" ixy="0" ixz="0" iyy="0.000035" iyz="0" izz="0.000004" />
  </inertial>
  <visual>
    <origin xyz="0 0 0" rpy="0 0 0" />
    <geometry>
      <mesh filename="/home/blandry/.julia/dev/Bilevel/urdf/little_dog/meshes/front_right_lower.obj"/>
    </geometry>
    <material name="black"/>
  </visual>
  <!-- <collision group="right_lower_legs">
    <origin xyz="-0.0265 0 -0.048" />
    <geometry>
      <capsule radius="0.012" length="0.09" />
    </geometry>
  </collision> -->
  <collision group="feet">
    <origin xyz="-0.0265 0 -0.0985"/>
    <geometry>
      <sphere radius="0"/>
    </geometry>
  </collision>
</link>

<joint name="front_right_knee" type="revolute">
  <parent link="front_right_upper_leg" />
  <child link="front_right_lower_leg" />
  <origin xyz="0 0 -0.0751" />
  <axis xyz="0 1 0" />
  <limit lower="-3.1" upper="1.0"/>
</joint>



<link name="back_left_hip">
  <inertial>
    <origin xyz="0.000000 0.002900 0.000000" rpy="0 0 0" />
    <mass value="0.062300" />
    <inertia ixx="0.000004" ixy="0" ixz="0" iyy="0.000015" iyz="0" izz="0.000015" />
  </inertial>
</link>

<joint name="back_left_hip_roll" type="revolute">
  <parent link="body" />
  <child link="back_left_hip" />
  <origin xyz="-0.101000 0.036250 0.000000" />
  <axis xyz="1 0 0" />
  <limit lower="-.6" upper=".6"/>
</joint>

<link name="back_left_upper_leg">
  <inertial>
    <origin xyz="0.000000 0.000000 -0.016600" rpy="0 0 0" />
    <mass value="0.127900" />
    <inertia ixx="0.000082" ixy="0" ixz="0" iyy="0.000089" iyz="0" izz="0.000015" />
  </inertial>
  <visual>
    <origin xyz="0 0 0" rpy="0 0 0" />
    <geometry>
      <mesh filename="/home/blandry/.julia/dev/Bilevel/urdf/little_dog/meshes/back_left_upper.obj"/>
    </geometry>
    <material name="black" />
  </visual>
</link>

<joint name="back_left_hip_pitch" type="revolute">
  <parent link="back_left_hip" />
  <child link="back_left_upper_leg" />
  <origin xyz="0 0.0236 0" />
  <axis xyz="0 1 0" />
  <limit lower="-2.4" upper="3.5"/>
</joint>

<link name="back_left_lower_leg">
  <inertial>
    <origin xyz="0.000000 0.000000 -0.020200" rpy="0 0 0" />
    <mass value="0.046400" />
    <inertia ixx="0.000038" ixy="0" ixz="0" iyy="0.000035" iyz="0" izz="0.000004" />
  </inertial>
  <visual>
    <origin xyz="0 0 0" rpy="0 0 0" />
    <geometry>
      <mesh filename="/home/blandry/.julia/dev/Bilevel/urdf/little_dog/meshes/back_left_lower.obj"/>
    </geometry>
    <material name="black" />
  </visual>
  <!-- <collision group="left_lower_legs">
    <origin xyz="0.0265 0 -0.048" />
    <geometry>
      <capsule radius="0.012" length="0.09" />
    </geometry>
  </collision> -->
  <collision group="feet">
    <origin xyz="0.0265 0 -0.0985"/>
    <geometry>
      <sphere radius="0"/>
    </geometry>
  </collision>
</link>

<joint name="back_left_knee" type="revolute">
  <parent link="back_left_upper_leg" />
  <child link="back_left_lower_leg" />
  <origin xyz="0 0 -0.0751" />
  <axis xyz="0 1 0" />
  <limit lower="-1.0" upper="3.1"/>
</joint>





<link name="back_right_hip">
  <inertial>
    <origin xyz="0.000000 -0.002900 0.000000" rpy="0 0 0" />
    <mass value="0.062300" />
    <inertia ixx="0.000004" ixy="0" ixz="0" iyy="0.000015" iyz="0" izz="0.000015" />
  </inertial>
</link>

<joint name="back_right_hip_roll" type="revolute">
  <parent link="body" />
  <child link="back_right_hip" />
  <origin xyz="-0.101000 -0.036250 0.000000" />
  <axis xyz="1 0 0" />
  <limit lower="-.6" upper=".6"/>
</joint>

<link name="back_right_upper_leg">
  <inertial>
    <origin xyz="0.000000 0.000000 -0.016600" rpy="0 0 0" />
    <mass value="0.127900" />
    <inertia ixx="0.000082" ixy="0" ixz="0" iyy="0.000089" iyz="0" izz="0.000015" />
  </inertial>
  <visual>
    <origin xyz="0 0 0" rpy="0 0 0" />
    <geometry>
      <mesh filename="/home/blandry/.julia/dev/Bilevel/urdf/little_dog/meshes/back_right_upper.obj"/>
    </geometry>
    <material name="black" />
  </visual>
</link>

<joint name="back_right_hip_pitch" type="revolute">
  <parent link="back_right_hip" />
  <child link="back_right_upper_leg" />
  <origin xyz="0 -0.0207 0" />
  <axis xyz="0 1 0" />
  <limit lower="-2.4" upper="3.5"/>
</joint>

<link name="back_right_lower_leg">
    <inertial>
      <origin xyz="0.000000 0.000000 -0.020200" rpy="0 0 0" />
      <mass value="0.046400" />
      <inertia ixx="0.000038" ixy="0" ixz="0" iyy="0.000035" iyz="0" izz="0.000004" />
    </inertial>
    <visual>
      <origin xyz="0 0 0" rpy="0 0 0" />
      <geometry>
        <mesh filename="/home/blandry/.julia/dev/Bilevel/urdf/little_dog/meshes/back_right_lower.obj"/>
      </geometry>
      <material name="black" />
    </visual>
    <!-- <collision group="right_lower_legs">
      <origin xyz="0.0265 0 -0.048" />
      <geometry>
        <capsule radius="0.012" length="0.09" />
      </geometry>
    </collision> -->
    <collision group="feet">
      <origin xyz="0.0265 0 -0.0985"/>
      <geometry>
        <sphere radius="0"/>
      </geometry>
    </collision>
  </link>

  <joint name="back_right_knee" type="revolute">
    <parent link="back_right_upper_leg" />
    <child link="back_right_lower_leg" />
    <origin xyz="0 0 -0.0751" />
    <axis xyz="0 1 0" />
    <limit lower="-1.0" upper="3.1"/>
  </joint>

</robot>
