<?xml version="1.0" ?>
<robot name="panda">
  <link name="panda_link0">
    <visual>
      <origin rpy="1.57079632679 0 0" xyz="0 0 0"/>
      <geometry>
        <mesh filename="../urdf/panda/meshes/link0.obj"/>
      </geometry>
    </visual>
    <inertial>
      <origin rpy="1.57079632679 0 0" xyz="0 0 0"/>
      <mass value="0.1" />
      <inertia ixx="0.03" iyy="0.03" izz="0.03" ixy="0.0" ixz="0.0" iyz="0.0" />
    </inertial>
  </link>
  <link name="panda_link1">
    <visual>
      <geometry>
        <mesh filename="../urdf/panda/meshes/link1.obj"/>
      </geometry>
    </visual>
    <inertial>
      <mass value="0.1" />
      <inertia ixx="0.03" iyy="0.03" izz="0.03" ixy="0.0" ixz="0.0" iyz="0.0" />
    </inertial>
  </link>
  <joint name="panda_joint1" type="revolute">
    <origin rpy="1.57079632679 0 0" xyz="0 0 0.333"/>
    <parent link="panda_link0"/>
    <child link="panda_link1"/>
    <axis xyz="0 1 0"/>
  </joint>
  <link name="panda_link2">
    <visual>
      <geometry>
        <mesh filename="../urdf/panda/meshes/link2.obj"/>
      </geometry>
    </visual>
    <inertial>
      <mass value="0.1" />
      <inertia ixx="0.03" iyy="0.03" izz="0.03" ixy="0.0" ixz="0.0" iyz="0.0" />
    </inertial>
  </link>
  <joint name="panda_joint2" type="revolute">
    <origin rpy="-1.57079632679 0 0" xyz="0 0 0"/>
    <parent link="panda_link1"/>
    <child link="panda_link2"/>
    <axis xyz="0 1 0"/>
  </joint>
  <link name="panda_link3">
    <visual>
      <geometry>
        <mesh filename="../urdf/panda/meshes/link3.obj"/>
      </geometry>
    </visual>
    <inertial>
      <mass value="0.1" />
      <inertia ixx="0.03" iyy="0.03" izz="0.03" ixy="0.0" ixz="0.0" iyz="0.0" />
    </inertial>
  </link>
  <joint name="panda_joint3" type="revolute">
    <origin rpy="1.57079632679 0 0" xyz="0 0 0.316"/>
    <parent link="panda_link2"/>
    <child link="panda_link3"/>
    <axis xyz="0 1 0"/>
  </joint>
  <link name="panda_link4">
    <visual>
      <geometry>
        <mesh filename="../urdf/panda/meshes/link4.obj"/>
      </geometry>
    </visual>
    <inertial>
      <mass value="0.1" />
      <inertia ixx="0.03" iyy="0.03" izz="0.03" ixy="0.0" ixz="0.0" iyz="0.0" />
    </inertial>
  </link>
  <joint name="panda_joint4" type="revolute">
    <origin rpy="1.57079632679 0 0" xyz="0.0825 0 0"/>
    <parent link="panda_link3"/>
    <child link="panda_link4"/>
    <axis xyz="0 1 0"/>
  </joint>
  <link name="panda_link5">
    <visual>
      <geometry>
        <mesh filename="../urdf/panda/meshes/link5.obj"/>
      </geometry>
    </visual>
    <inertial>
      <mass value="0.1" />
      <inertia ixx="0.03" iyy="0.03" izz="0.03" ixy="0.0" ixz="0.0" iyz="0.0" />
    </inertial>
  </link>
  <joint name="panda_joint5" type="revolute">
    <origin rpy="-1.57079632679 0 0" xyz="-0.0825 0 -0.384"/>
    <parent link="panda_link4"/>
    <child link="panda_link5"/>
    <axis xyz="0 1 0"/>
  </joint>
  <link name="panda_link6">
    <visual>
      <geometry>
        <mesh filename="../urdf/panda/meshes/link6.obj"/>
      </geometry>
    </visual>
    <inertial>
      <mass value="0.1" />
      <inertia ixx="0.03" iyy="0.03" izz="0.03" ixy="0.0" ixz="0.0" iyz="0.0" />
    </inertial>
  </link>
  <joint name="panda_joint6" type="revolute">
    <origin rpy="1.57079632679 0 0" xyz="0 0 0"/>
    <parent link="panda_link5"/>
    <child link="panda_link6"/>
    <axis xyz="0 1 0"/>
  </joint>
  <link name="panda_link7">
    <visual>
      <geometry>
        <mesh filename="../urdf/panda/meshes/link7.obj"/>
      </geometry>
    </visual>
    <inertial>
      <mass value="0.1" />
      <inertia ixx="0.03" iyy="0.03" izz="0.03" ixy="0.0" ixz="0.0" iyz="0.0" />
    </inertial>
  </link>
  <joint name="panda_joint7" type="revolute">
    <origin rpy="1.57079632679 0 0" xyz="0.088 0 0"/>
    <parent link="panda_link6"/>
    <child link="panda_link7"/>
    <axis xyz="0 1 0"/>
  </joint>
  <link name="panda_link8">
    <visual>
      <geometry>
        <box size=".35 .35 .01"/>
      </geometry>
      <material name="blue">
        <color rgba=".28125 .23828 .542968 1."/>
      </material>
      <!-- <material name="green">
        <color rgba=".1328 .54296 .1328 1."/>
      </material> -->
    </visual>
    <inertial>
      <mass value="0.1" />
      <inertia ixx="0.03" iyy="0.03" izz="0.03" ixy="0.0" ixz="0.0" iyz="0.0" />
    </inertial>
  </link>
  <joint name="panda_joint8" type="fixed">
    <origin rpy="-1.57079632679 0 0" xyz="0 0.11 0"/>
    <parent link="panda_link7"/>
    <child link="panda_link8"/>
  </joint>
</robot>
