<?xml version="1.0" ?>
<robot name="panda">
  
  <link name="floor">
    <visual>
      <origin xyz="4 0 -0.05"/>
      <geometry>
        <box size="10 2 0.1"/>
      </geometry>
    </visual>
    <collision>
      <origin xyz="4 0 -0.05"/>
      <geometry>
        <box size="10 2 0.1"/>
        <plane normal="0 0 1"/>
      </geometry>
    </collision>
  </link>
  
  <link name="box">
  <visual>
    <geometry>
      <box size=".5 .5 .5"/>
    </geometry>
    <origin xyz="0 0 0"/>
    <material name="green">
      <color rgba="0 0.8 .8 .8"/>
    </material>
  </visual>
  <inertial>
    <mass value="1."/>
    <inertia ixx="1." ixy="0." ixz="0." iyy="1." iyz="0." izz="1."/>
  </inertial>
  <collision>
    <origin xyz="0 0 0"/>
    <geometry>
      <box size=".5 .5 .5"/>
      <plane normal="-1 0 0"/>
    </geometry>
  </collision>
  </link>
  <joint name="floor_to_box" type="fixed">
    <parent link="floor"/>
    <child link="box"/>
    <origin xyz="1 0 .25"/>
  </joint>
  
  <link name="contact1">
  <visual>
    <geometry>
      <sphere radius=".05"/>
    </geometry>
    <origin xyz="0. 0. 0."/>
    <material name="green">
      <color rgba="0 0.1 .2 1."/>
    </material>
  </visual>
  <inertial>
    <mass value="1e-12"/>
    <inertia ixx="1e-12" ixy="0." ixz="0." iyy="1e-12" iyz="0." izz="1e-12"/>
  </inertial>
  <collision>
    <origin xyz="0. 0. 0."/>
    <geometry>
      <sphere radius="0"/>
    </geometry>
  </collision>
  </link>
  <joint name="contact1_to_box" type="fixed">
    <origin xyz="0 0 -.25"/>
    <parent link="box"/>
    <child link="contact1"/>
  </joint>
  
  <link name="panda_link0">
    <visual>
      <geometry>
        <mesh filename="../urdf/panda/meshes/link0.obj"/>
      </geometry>
    </visual>
    <inertial>
      <mass value="0.1" />
      <inertia ixx="0.03" iyy="0.03" izz="0.03" ixy="0.0" ixz="0.0" iyz="0.0" />
    </inertial>
  </link>
  <joint name="panda_joint0" type="fixed">
    <origin rpy="1.57079632679 0 0" xyz="0 0 0"/>
    <parent link="floor"/>
    <child link="panda_link0"/>
  </joint>

  <link name="panda_link1">
    <visual>
      <geometry>
        <mesh filename="../urdf/panda/meshes/link1.obj"/>
      </geometry>
    </visual>
    <inertial>
      <mass value="0.1" />
      <inertia ixx="0.03" iyy="0.03" izz="0.03" ixy="0.0" ixz="0.0" iyz="0.0" />
    </inertial>
  </link>
  <joint name="panda_joint1" type="revolute">
    <origin rpy="0 0 0" xyz="0 .333 0"/>
    <parent link="panda_link0"/>
    <child link="panda_link1"/>
    <axis xyz="0 1 0"/>
  </joint>
  
  <link name="panda_link2">
    <visual>
      <geometry>
        <mesh filename="../urdf/panda/meshes/link2.obj"/>
      </geometry>
    </visual>
    <inertial>
      <mass value="0.1" />
      <inertia ixx="0.03" iyy="0.03" izz="0.03" ixy="0.0" ixz="0.0" iyz="0.0" />
    </inertial>
  </link>
  <joint name="panda_joint2" type="revolute">
    <origin rpy="-1.57079632679 0 0" xyz="0 0 0"/>
    <parent link="panda_link1"/>
    <child link="panda_link2"/>
    <axis xyz="0 1 0"/>
  </joint>
  
  <link name="panda_link3">
    <visual>
      <geometry>
        <mesh filename="../urdf/panda/meshes/link3.obj"/>
      </geometry>
    </visual>
    <inertial>
      <mass value="0.1" />
      <inertia ixx="0.03" iyy="0.03" izz="0.03" ixy="0.0" ixz="0.0" iyz="0.0" />
    </inertial>
  </link>
  <joint name="panda_joint3" type="revolute">
    <origin rpy="1.57079632679 0 0" xyz="0 0 0.316"/>
    <parent link="panda_link2"/>
    <child link="panda_link3"/>
    <axis xyz="0 1 0"/>
  </joint>
  
  <link name="panda_link4">
    <visual>
      <geometry>
        <mesh filename="../urdf/panda/meshes/link4.obj"/>
      </geometry>
    </visual>
    <inertial>
      <mass value="0.1" />
      <inertia ixx="0.03" iyy="0.03" izz="0.03" ixy="0.0" ixz="0.0" iyz="0.0" />
    </inertial>
  </link>
  <joint name="panda_joint4" type="revolute">
    <origin rpy="1.57079632679 0 0" xyz="0.0825 0 0"/>
    <parent link="panda_link3"/>
    <child link="panda_link4"/>
    <axis xyz="0 1 0"/>
  </joint>
  
  <link name="panda_link5">
    <visual>
      <geometry>
        <mesh filename="../urdf/panda/meshes/link5.obj"/>
      </geometry>
    </visual>
    <inertial>
      <mass value="0.1" />
      <inertia ixx="0.03" iyy="0.03" izz="0.03" ixy="0.0" ixz="0.0" iyz="0.0" />
    </inertial>
  </link>
  <joint name="panda_joint5" type="revolute">
    <origin rpy="-1.57079632679 0 0" xyz="-0.0825 0 -0.384"/>
    <parent link="panda_link4"/>
    <child link="panda_link5"/>
    <axis xyz="0 1 0"/>
  </joint>
  
  <link name="panda_link6">
    <visual>
      <geometry>
        <mesh filename="../urdf/panda/meshes/link6.obj"/>
      </geometry>
    </visual>
    <inertial>
      <mass value="0.1" />
      <inertia ixx="0.03" iyy="0.03" izz="0.03" ixy="0.0" ixz="0.0" iyz="0.0" />
    </inertial>
  </link>
  <joint name="panda_joint6" type="revolute">
    <origin rpy="1.57079632679 0 0" xyz="0 0 0"/>
    <parent link="panda_link5"/>
    <child link="panda_link6"/>
    <axis xyz="0 1 0"/>
  </joint>
  
  <link name="panda_link7">
    <visual>
      <geometry>
        <mesh filename="../urdf/panda/meshes/link7.obj"/>
      </geometry>
    </visual>
    <inertial>
      <mass value="0.1" />
      <inertia ixx="0.03" iyy="0.03" izz="0.03" ixy="0.0" ixz="0.0" iyz="0.0" />
    </inertial>
  </link>
  <joint name="panda_joint7" type="revolute">
    <origin rpy="1.57079632679 0 0" xyz="0.088 0 0"/>
    <parent link="panda_link6"/>
    <child link="panda_link7"/>
    <axis xyz="0 1 0"/>
  </joint>
  
  <link name="panda_link8">
    <visual>
      <geometry>
        <sphere radius=".025"/>
      </geometry>
      <material name="blue">
        <color rgba="0 0.4 .6 1."/>
      </material>
    </visual>
    <inertial>
      <mass value="0.1" />
      <inertia ixx="0.03" iyy="0.03" izz="0.03" ixy="0.0" ixz="0.0" iyz="0.0" />
    </inertial>
    <collision>
      <origin xyz="0. 0. 0."/>
      <geometry>
        <sphere radius="0"/>
      </geometry>
    </collision>
  </link>
  <joint name="panda_joint8" type="fixed">
    <origin rpy="0 0 0" xyz="0 .1 0"/>
    <parent link="panda_link7"/>
    <child link="panda_link8"/>
  </joint>
</robot>
